Workbook

Sheet 说明
A1: Compass 验收测试用例
A3: 怎么用 | B3: 在「测试用例」表的【状态】列选:未测试/通过/不通过/阻塞/不适用。「统计」表会自动汇总。
B4: 不通过的把现象写进【实际结果/备注】列,连同页面地址和服务端日志一起反馈。
A6: 红线标记 | B6: 【红线】列标「红线」的是合规/安全底线,不通过必须停下修,不能放行接真实用户。
A8: 测试环境 | B8: 演示服 http://8.208.125.209 或 本地 http://localhost:3000
A10: 必做的准备 | B10: 先完成编号 P1–P4。特别是 P4「开放英国地区」——不做的话前台一直是空的,
B11: 会让你误以为功能坏了。所有地区默认关闭是设计如此:数据没核对完就不放出去。
A13: 演示环境已知限制 | B13: 以下不可测,不是 bug:
B14: · 真实支付——mock,点确认即视为付款成功
B15: · 真实短信——需 ALLOW_MOCK_SMS=true,验证码只写入服务端日志
B16: · 真实 LLM——mock,AI 返回固定占位内容
B17: · 对象存储——材料存本机磁盘(已 AES-256-GCM 加密)
A19: 反馈问题时请附 | B19: 1) 页面地址 2) 操作步骤 3) 预期 vs 实际 4) journalctl -u compass -n 50 --no-pager

Sheet 测试用例
A1: 编号 | B1: 模块 | C1: 红线 | D1: 操作步骤 | E1: 预期结果 | F1: 状态 | G1: 实际结果/备注 | H1: 测试日期
A2: P1 | B2: 〇 测试准备 | D2: 服务器执行 curl -s localhost:3000/api/health | E2: 返回 {"ok":true}。这条会真的查数据库——首页返回200不代表数据库通 | F2: 未测试
A3: P2 | B3: 〇 测试准备 | D3: 执行 ADMIN_EMAIL=你的邮箱 npm run admin:create | E3: 打印后台邮箱与密码(只打印一次,当场存好) | F3: 未测试
A4: P3 | B4: 〇 测试准备 | D4: 执行 PHONE=13800138000 PASSWORD='至少12位' npm run demo:seed | E4: 打印手机号与密码,并显示「选校单5所 / 材料清单N项」 | F4: 未测试
A5: P4 | B5: 〇 测试准备 | D5: 登录后台 → 地区开放 → 打开【英国】 | E5: 不做这步前台永远是空的(设计如此:数据没核对完不放出去) | F5: 未测试
A6: A1 | B6: 一 营销首页 | D6: 打开首页 / | E6: 显示项目数/院校数/地区数,数字来自数据库(开放英国后不为0) | F6: 未测试
A7: A2 | B7: 一 营销首页 | D7: 未登录时看顶部导航 | E7: 显示「价格 / 登录·注册 / 免费测一测」 | F7: 未测试
A8: A3 | B8: 一 营销首页 | D8: 登录后再回首页 | E8: 「登录/注册」变成「进入工作台」 | F8: 未测试
A9: A4 | B9: 一 营销首页 | C9: 红线 | D9: 通读全页与FAQ,搜索敏感词 | E9: 不得出现「保录」「保offer」「100%成功」「包过」「轻松」 | F9: 未测试
A10: A5 | B10: 一 营销首页 | C10: 红线 | D10: 看FAQ「能保证录取吗」 | E10: 明确回答不能保证,给出的是参考区间 | F10: 未测试
A11: A6 | B11: 一 营销首页 | D11: 看FAQ「买了觉得不合适怎么办」 | E11: 写明退款规则(7天/3次、阶梯退、单点服务三档) | F11: 未测试
A12: A7 | B12: 一 营销首页 | D12: 看页脚声明 | E12: 有「不做学科培训、不代理申请、不承诺录取结果」 | F12: 未测试
A13: A8 | B13: 一 营销首页 | D13: F12切手机尺寸打开首页 | E13: 布局不横向溢出,按钮可点(触控目标≥44px) | F13: 未测试
A14: B1 | B14: 二 免费评估 | D14: 点「免费测一测」进入 /assess | E14: 3步表单,顶部有步骤指示 1/3 | F14: 未测试
A15: B2 | B15: 二 免费评估 | D15: 第1步选本科层级+学科门类 | E15: 两项都选完才能进入下一步 | F15: 未测试
A16: B3 | B16: 二 免费评估 | D16: 第2步拖动GPA滑块,切换百分制/4分制 | E16: 数字实时变化;切换后取值范围跟着变 | F16: 未测试
A17: B4 | B17: 二 免费评估 | D17: 第2步语言选「雅思」 | E17: 出现两个输入框:总分、最低单项 | F17: 未测试
A18: B5 | B18: 二 免费评估 | D18: 第2步看小分说明文案 | E18: 提示「很多学校要求总分6.5且单项不低于6.0」 | F18: 未测试
A19: B6 | B19: 二 免费评估 | D19: 第2步语言选「还没考」 | E19: 分数输入框消失,仍可继续 | F19: 未测试
A20: B7 | B20: 二 免费评估 | D20: 第3步查看地区列表 | E20: 只列已开放且真有数据的地区,每个带项目数 | F20: 未测试
A21: B8 | B21: 二 免费评估 | D21: 第3步查看方向列表 | E21: 按第1步的学科门类排序,分「顺延/转向」分组 | F21: 未测试
A22: B9 | B22: 二 免费评估 | D22: 点「查看更多跨学科方向」 | E22: 展开剩余方向,再点可收起 | F22: 未测试
... A26: B13 | B26: 二 免费评估 | D26: 结果页查看名单 | E26: 分「冲刺 / 匹配 / 稳妥」三档 | F26: 未测试
A27: B14 | B27: 二 免费评估 | C27: 红线 | D27: 结果页查看每个项目的录取概率 | E27: 标注为预估区间(如30–45%),不是单一确定数字 | F27: 未测试
A28: B15 | B28: 二 免费评估 | C28: 红线 | D28: 结果页查看免责声明 | E28: 写明预估仅供参考、以学校官网为准 | F28: 未测试
A29: B16 | B29: 二 免费评估 | C29: 红线 | D29: 结果页查看未核对的数据项 | E29: 明确标注「待核实」,不当作确定值展示 | F29: 未测试
A30: B17 | B30: 二 免费评估 | D30: 填最低单项5.5+总分7.0,看语言体检 | E30: 总分够但单项不够的项目不算达标(对比不填单项时达标数应更多) | F30: 未测试
A31: B18 | B31: 二 免费评估 | D31: 点分享按钮 | E31: 生成分享链接,/r/[code] 可正常打开 | F31: 未测试
A32: C1 | B32: 三 注册登录 | D32: 打开 /login | E32: 顶部有「验证码登录 / 密码登录」切换;标题为「登录 / 注册」 | F32: 未测试
A33: C2 | B33: 三 注册登录 | D33: 验证码模式下查看顶部 | E33: 有「① 填手机号 → ② 填验证码登录」两步指示 | F33: 未测试
A34: C3 | B34: 三 注册登录 | D34: 刚进入登录页 | E34: 光标自动定位在手机号输入框 | F34: 未测试
A35: C4 | B35: 三 注册登录 | D35: 手机号填不满11位 | E35: 「获取验证码」按钮灰着点不动 | F35: 未测试
A36: C5 | B36: 三 注册登录 | D36: 不勾选用户协议 | E36: 按钮点不动 | F36: 未测试
A37: C6 | B37: 三 注册登录 | D37: 本地环境点「获取验证码」 | E37: 页面显示验证码,并有「一键填入」按钮 | F37: 未测试
A38: C7 | B38: 三 注册登录 | D38: 服务器点「获取验证码」,同时看服务端日志 | E38: 页面不显示验证码;journalctl -u compass -f | grep SMS:demo 里能看到 | F38: 未测试
A39: C8 | B39: 三 注册登录 | D39: 验证码发出后 | E39: 光标自动跳到验证码输入框 | F39: 未测试
A40: C9 | B40: 三 注册登录 | C40: 红线 | D40: 故意输错验证码5次,然后输入正确的码 | E40: 第5次提示「错误次数过多」;此后即使输对也进不去,必须重新发码 | F40: 未测试
A41: C10 | B41: 三 注册登录 | D41: 60秒内重复点「获取验证码」 | E41: 提示「请60秒后再试」 | F41: 未测试
A42: C11 | B42: 三 注册登录 | D42: 用全新手机号+正确验证码登录 | E42: 自动创建账号,跳转到 /app/onboarding | F42: 未测试
A43: C12 | B43: 三 注册登录 | D43: 切换到「密码登录」 | E43: 协议勾选框消失(密码登录不建新号),出现密码输入框 | F43: 未测试
...

Sheet 统计
A1: 测试进度统计
A2: （数据自动汇总自「测试用例」表，无需手动填写）
A4: 总用例数 | B4: =COUNTA(测试用例!A2:A144) -> 143
A5: 已通过 | B5: =COUNTIF(测试用例!F2:F144,"通过") -> 0
A6: 不通过 | B6: =COUNTIF(测试用例!F2:F144,"不通过") -> 0
A7: 阻塞 | B7: =COUNTIF(测试用例!F2:F144,"阻塞") -> 0
A8: 不适用 | B8: =COUNTIF(测试用例!F2:F144,"不适用") -> 0
A9: 未测试 | B9: =COUNTIF(测试用例!F2:F144,"未测试") -> 143
A10: 完成率 | B10: =IF(B4=0,0,(B4-B9)/B4) -> 0
A12: 红线用例总数 | B12: =COUNTIF(测试用例!C2:C144,"红线") -> 45
A13: 红线-已通过 | B13: =COUNTIFS(测试用例!C2:C144,"红线",测试用例!F2:F144,"通过") -> 0
A14: 红线-不通过 | B14: =COUNTIFS(测试用例!C2:C144,"红线",测试用例!F2:F144,"不通过") -> 0
A15: 红线-未测试 | B15: =COUNTIFS(测试用例!C2:C144,"红线",测试用例!F2:F144,"未测试") -> 45
A17: 放行判断 | B17: =IF(B14>0,"禁止放行:有红线用例不通过",IF(B15>0,"尚未测完红线用例",IF(B6>0,"有普通用例不通过,可评估后放行","红线全部通过"))) -> 尚未测完红线用例
A19: 分模块统计
A20: 模块 | B20: 用例数 | C20: 通过 | D20: 不通过 | E20: 未测试
A21: 〇 测试准备 | B21: =COUNTIF(测试用例!B2:B144,A21) -> 4 | C21: =COUNTIFS(测试用例!B2:B144,A21,测试用例!F2:F144,"通过") -> 0 | D21: =COUNTIFS(测试用例!B2:B144,A21,测试用例!F2:F144,"不通过") -> 0 | E21: =COUNTIFS(测试用例!B2:B144,A21,测试用例!F2:F144,"未测试") -> 4
A22: 一 营销首页 | B22: =COUNTIF(测试用例!B2:B144,A22) -> 8 | C22: =COUNTIFS(测试用例!B2:B144,A22,测试用例!F2:F144,"通过") -> 0 | D22: =COUNTIFS(测试用例!B2:B144,A22,测试用例!F2:F144,"不通过") -> 0 | E22: =COUNTIFS(测试用例!B2:B144,A22,测试用例!F2:F144,"未测试") -> 8
A23: 二 免费评估 | B23: =COUNTIF(测试用例!B2:B144,A23) -> 18 | C23: =COUNTIFS(测试用例!B2:B144,A23,测试用例!F2:F144,"通过") -> 0 | D23: =COUNTIFS(测试用例!B2:B144,A23,测试用例!F2:F144,"不通过") -> 0 | E23: =COUNTIFS(测试用例!B2:B144,A23,测试用例!F2:F144,"未测试") -> 18
A24: 三 注册登录 | B24: =COUNTIF(测试用例!B2:B144,A24) -> 16 | C24: =COUNTIFS(测试用例!B2:B144,A24,测试用例!F2:F144,"通过") -> 0 | D24: =COUNTIFS(测试用例!B2:B144,A24,测试用例!F2:F144,"不通过") -> 0 | E24: =COUNTIFS(测试用例!B2:B144,A24,测试用例!F2:F144,"未测试") -> 16
A25: 四 定价支付 | B25: =COUNTIF(测试用例!B2:B144,A25) -> 6 | C25: =COUNTIFS(测试用例!B2:B144,A25,测试用例!F2:F144,"通过") -> 0 | D25: =COUNTIFS(测试用例!B2:B144,A25,测试用例!F2:F144,"不通过") -> 0 | E25: =COUNTIFS(测试用例!B2:B144,A25,测试用例!F2:F144,"未测试") -> 6
A26: 五 工作台-总览 | B26: =COUNTIF(测试用例!B2:B144,A26) -> 4 | C26: =COUNTIFS(测试用例!B2:B144,A26,测试用例!F2:F144,"通过") -> 0 | D26: =COUNTIFS(测试用例!B2:B144,A26,测试用例!F2:F144,"不通过") -> 0 | E26: =COUNTIFS(测试用例!B2:B144,A26,测试用例!F2:F144,"未测试") -> 4
A27: 五 工作台-评估 | B27: =COUNTIF(测试用例!B2:B144,A27) -> 9 | C27: =COUNTIFS(测试用例!B2:B144,A27,测试用例!F2:F144,"通过") -> 0 | D27: =COUNTIFS(测试用例!B2:B144,A27,测试用例!F2:F144,"不通过") -> 0 | E27: =COUNTIFS(测试用例!B2:B144,A27,测试用例!F2:F144,"未测试") -> 9
A28: 五 工作台-选校 | B28: =COUNTIF(测试用例!B2:B144,A28) -> 5 | C28: =COUNTIFS(测试用例!B2:B144,A28,测试用例!F2:F144,"通过") -> 0 | D28: =COUNTIFS(测试用例!B2:B144,A28,测试用例!F2:F144,"不通过") -> 0 | E28: =COUNTIFS(测试用例!B2:B144,A28,测试用例!F2:F144,"未测试") -> 5
A29: 五 工作台-材料 | B29: =COUNTIF(测试用例!B2:B144,A29) -> 7 | C29: =COUNTIFS(测试用例!B2:B144,A29,测试用例!F2:F144,"通过") -> 0 | D29: =COUNTIFS(测试用例!B2:B144,A29,测试用例!F2:F144,"不通过") -> 0 | E29: =COUNTIFS(测试用例!B2:B144,A29,测试用例!F2:F144,"未测试") -> 7
A30: 五 工作台-文书 | B30: =COUNTIF(测试用例!B2:B144,A30) -> 6 | C30: =COUNTIFS(测试用例!B2:B144,A30,测试用例!F2:F144,"通过") -> 0 | D30: =COUNTIFS(测试用例!B2:B144,A30,测试用例!F2:F144,"不通过") -> 0 | E30: =COUNTIFS(测试用例!B2:B144,A30,测试用例!F2:F144,"未测试") -> 6
A31: 五 工作台-服务 | B31: =COUNTIF(测试用例!B2:B144,A31) -> 2 | C31: =COUNTIFS(测试用例!B2:B144,A31,测试用例!F2:F144,"通过") -> 0 | D31: =COUNTIFS(测试用例!B2:B144,A31,测试用例!F2:F144,"不通过") -> 0 | E31: =COUNTIFS(测试用例!B2:B144,A31,测试用例!F2:F144,"未测试") -> 2
A32: 五 工作台-设置 | B32: =COUNTIF(测试用例!B2:B144,A32) -> 4 | C32: =COUNTIFS(测试用例!B2:B144,A32,测试用例!F2:F144,"通过") -> 0 | D32: =COUNTIFS(测试用例!B2:B144,A32,测试用例!F2:F144,"不通过") -> 0 | E32: =COUNTIFS(测试用例!B2:B144,A32,测试用例!F2:F144,"未测试") -> 4
A33: 五 工作台-移动端 | B33: =COUNTIF(测试用例!B2:B144,A33) -> 4 | C33: =COUNTIFS(测试用例!B2:B144,A33,测试用例!F2:F144,"通过") -> 0 | D33: =COUNTIFS(测试用例!B2:B144,A33,测试用例!F2:F144,"不通过") -> 0 | E33: =COUNTIFS(测试用例!B2:B144,A33,测试用例!F2:F144,"未测试") -> 4
A34: 六 运营后台 | B34: =COUNTIF(测试用例!B2:B144,A34) -> 4 | C34: =COUNTIFS(测试用例!B2:B144,A34,测试用例!F2:F144,"通过") -> 0 | D34: =COUNTIFS(测试用例!B2:B144,A34,测试用例!F2:F144,"不通过") -> 0 | E34: =COUNTIFS(测试用例!B2:B144,A34,测试用例!F2:F144,"未测试") -> 4
A35: 六 后台-院校库 | B35: =COUNTIF(测试用例!B2:B144,A35) -> 10 | C35: =COUNTIFS(测试用例!B2:B144,A35,测试用例!F2:F144,"通过") -> 0 | D35: =COUNTIFS(测试用例!B2:B144,A35,测试用例!F2:F144,"不通过") -> 0 | E35: =COUNTIFS(测试用例!B2:B144,A35,测试用例!F2:F144,"未测试") -> 10
A36: 六 后台-其他 | B36: =COUNTIF(测试用例!B2:B144,A36) -> 12 | C36: =COUNTIFS(测试用例!B2:B144,A36,测试用例!F2:F144,"通过") -> 0 | D36: =COUNTIFS(测试用例!B2:B144,A36,测试用例!F2:F144,"不通过") -> 0 | E36: =COUNTIFS(测试用例!B2:B144,A36,测试用例!F2:F144,"未测试") -> 12
A37: 七 顾问端 | B37: =COUNTIF(测试用例!B2:B144,A37) -> 4 | C37: =COUNTIFS(测试用例!B2:B144,A37,测试用例!F2:F144,"通过") -> 0 | D37: =COUNTIFS(测试用例!B2:B144,A37,测试用例!F2:F144,"不通过") -> 0 | E37: =COUNTIFS(测试用例!B2:B144,A37,测试用例!F2:F144,"未测试") -> 4
A38: 八 安全权限 | B38: =COUNTIF(测试用例!B2:B144,A38) -> 10 | C38: =COUNTIFS(测试用例!B2:B144,A38,测试用例!F2:F144,"通过") -> 0 | D38: =COUNTIFS(测试用例!B2:B144,A38,测试用例!F2:F144,"不通过") -> 0 | E38: =COUNTIFS(测试用例!B2:B144,A38,测试用例!F2:F144,"未测试") -> 10
A39: 九 合规红线 | B39: =COUNTIF(测试用例!B2:B144,A39) -> 10 | C39: =COUNTIFS(测试用例!B2:B144,A39,测试用例!F2:F144,"通过") -> 0 | D39: =COUNTIFS(测试用例!B2:B144,A39,测试用例!F2:F144,"不通过") -> 0 | E39: =COUNTIFS(测试用例!B2:B144,A39,测试用例!F2:F144,"未测试") -> 10

Sheet 上线前检查
A1: 上线前必须完成的事项（不是代码问题）
A2: 这些与功能测试无关，但接真实用户前必须逐项落实。
A4: 编号 | B4: 事项 | C4: 说明 | D4: 紧急度 | E4: 状态
A5: L1 | B5: 换境内地域服务器 | C5: 当前IP在阿里云国际站段,备案办不下来;域名在国内和微信里都打不开 | D5: 阻塞上线 | E5: 未开始
A6: L2 | B6: 接入阿里云短信 | C6: 现在是mock,需删除 ALLOW_MOCK_SMS 开关;需要营业执照 | D6: 阻塞上线 | E6: 未开始
A7: L3 | B7: 接入微信支付(收款+退款一起) | C7: 现在退款只改状态、不真退钱;需商户号 | D7: 阻塞上线 | E7: 未开始
A8: L4 | B8: 法律文本送律师定稿 | C8: 当前 /legal/terms 与 /legal/privacy 是技术草稿 | D8: 阻塞上线 | E8: 未开始
A9: L5 | B9: 核对英国126条院校数据 | C9: 核对率达标后把地区开放门槛调回90% | D9: 阻塞上线 | E9: 未开始
A10: L6 | B10: 材料迁移到OSS | C10: 私有桶 + 服务端加密 + 签名URL;现在存本机磁盘(已加密) | D10: 强烈建议 | E10: 未开始
A11: L7 | B11: 配置HTTPS | C11: certbot --nginx,并把 NEXT_PUBLIC_SITE_URL 改成 https:// | D11: 强烈建议 | E11: 未开始
A12: L8 | B12: 备份+异地+恢复演练 | C12: 数据库与uploads都要备;见 deploy/云上安全.md | D12: 强烈建议 | E12: 未开始
